Workbook

Sheet Сводка
A1: Автоматические тесты — сводка
A2: Список собран из самого pytest (сбор тестов без запуска) и docstring-ов; актуален на дату сборки файла.
A4: Уровень | B4: Тестов (функций) | C4: Кейсов | D4: Что проверяет уровень
A5: модульные | B5: =COUNTIF('Тесты'!$B$2:$B$718,A5) | C5: =SUMIF('Тесты'!$B$2:$B$718,A5,'Тесты'!$G$2:$G$718) | D5: Отдельные модули без сети: справочник типов, конечный автомат, поиск, обезличивание, лимиты, ответчики по тарифам и отключениям, сессии, шаблоны бланков.
A6: контрактные | B6: =COUNTIF('Тесты'!$B$2:$B$718,A6) | C6: =SUMIF('Тесты'!$B$2:$B$718,A6,'Тесты'!$G$2:$G$718) | D6: Границы между частями: HTTP-контракт шлюза и спецификация API, порядок работы оркестратора и шлюза, контракт провайдера модели.
A7: Всего | B7: =SUM(B5:B6) | C7: =SUM(C5:C6) | D7: Кейс = один запуск; параметризованный тест даёт несколько кейсов.
A9: Итог обычного прогона (`python -m pytest`) | B9: Кейсов | D9: Комментарий
A10: Проходят | B10: =C7-B11-B12 | D10: Зелёные в обычном прогоне.
A11: Пропускаются (условие не выполнено на этой машине) | B11: 3 | D11: Три теста в test_metrics.py сверяют метрики со спецификацией дашборда; файла спецификации в пакете сдачи нет, поэтому они пропускаются.
A12: Выключены маркером `live` (нужна запущенная Ollama) | B12: 10 | D12: Запуск явно: `python -m pytest -m live`.
A13: Всего собрано | B13: =C7
A15: Как запустить
A16: python -m pytest — весь обычный прогон
A17: python -m pytest tests/unit — только модульные
A18: python -m pytest tests/contract — только контрактные
A19: python -m pytest -m live — живые тесты (нужна Ollama)

Sheet Тесты
A1: № | B1: Уровень | C1: Файл | D1: Класс | E1: Тест | F1: Что проверяет | G1: Кейсов | H1: Пометки
A2: 1 | B2: контрактные | C2: contract/test_api.py | E2: test_только_два_адреса_плюс_стенд | F2: Контракт — два адреса: /models удалён из контракта, лишнего быть не должно. | G2: 1
A3: 2 | B3: контрактные | C3: contract/test_api.py | E3: test_проверка_доступности_отвечает_без_авторизации | F3: Контракт: security: [] — заголовков не требуется. | G3: 1
A4: 3 | B4: контрактные | C4: contract/test_api.py | E4: test_ответ_приходит_потоком | F4: Ответ приходит потоком | G4: 1
A5: 4 | B5: контрактные | C5: contract/test_api.py | E5: test_события_потока_разделены_пустой_строкой | F5: Требование формата: иначе потребитель склеит два события в одно. | G5: 1
A6: 5 | B6: контрактные | C6: contract/test_api.py | E6: test_русский_текст_в_потоке_не_экранируется | F6: Иначе стенд показал бы абоненту последовательности вида \u043f. | G6: 1
A7: 6 | B7: контрактные | C7: contract/test_api.py | E7: test_ответ_целиком_приходит_обычным_json | F7: Ответ целиком приходит обычным json | G7: 1
A8: 7 | B8: контрактные | C8: contract/test_api.py | E8: test_неверный_запрос_даёт_400_в_формате_rfc7807 | F8: Неверный запрос даёт 400 в формате rfc7807 | G8: 1
A9: 8 | B9: контрактные | C9: contract/test_api.py | E9: test_слишком_длинный_запрос_отклоняется | F9: Ограничение длины запроса — 2000 символов. | G9: 1
A10: 9 | B10: контрактные | C10: contract/test_api.py | E10: test_у_отказов_есть_время_повтора | F10: RFC 7807 требует его для 429; ADR-400 — для 503. | G10: 2
A11: 10 | B11: контрактные | C11: contract/test_api.py | E11: test_ошибка_в_потоке_приходит_событием_с_тем_же_телом | F11: Решение 4 в моделях: один формат ошибки на оба пути. | G11: 1
A12: 11 | B12: контрактные | C12: contract/test_api.py | E12: test_идентификаторы_доходят_до_шлюза | F12: Без них не считаются лимиты и не пишется аудит. | G12: 1
A13: 12 | B13: контрактные | C13: contract/test_api.py | E13: test_стенд_отдаётся_по_корневому_адресу | F13: Только на прототипе: в рабочем контуре виджет живёт в кабинете абонента. | G13: 1
... A66: 65 | B66: контрактные | C66: contract/test_llm_gateway.py | E66: test_у_ошибки_есть_опознаватель_запроса | F66: Без него жалобу абонента невозможно связать с записью в журнале. | G66: 1
A67: 66 | B67: контрактные | C67: contract/test_llm_gateway.py | E67: test_живой_вызов_яндекса | F67: Сквозная проверка на реальном провайдере. Запускать: pytest -m live. | G67: 1 | H67: живой тест (нужна Ollama, в обычном прогоне выключен)
A68: 67 | B68: контрактные | C68: contract/test_llm_gateway.py | E68: test_внутренний_текст_ошибки_не_доходит_до_абонента | F68: Найдено живой проверкой: абоненту показывался адрес, порт и адрес объекта в памяти. И непонятно, и раскрывает устройство системы. | G68: 2
A69: 68 | B69: контрактные | C69: contract/test_llm_gateway.py | E69: test_внутренний_текст_не_доходит_и_в_потоке | F69: Тот же путь, второй режим: ошибка внутри уже начатого потока. | G69: 1
A70: 69 | B70: контрактные | C70: contract/test_llm_gateway.py | E70: test_прогрев_поднимает_тяжёлые_зависимости | F70: Найдено живой проверкой: восемь секунд до первого куска ответа. | G70: 1
A71: 70 | B71: контрактные | C71: contract/test_llm_gateway.py | E71: test_интерфейс_прогревает_шлюз_при_запуске | F71: Прогрев бесполезен, если его никто не вызывает. | G71: 1
A72: 71 | B72: контрактные | C72: contract/test_llm_gateway.py | E72: test_ответ_по_синтетике_помечен_оговоркой | F72: Ответ по выдуманной процедуре обязан быть отличим от ответа по настоящему регламенту — иначе на демонстрации его примут за второе. | G72: 1
A73: 72 | B73: контрактные | C73: contract/test_llm_gateway.py | E73: test_ответ_по_настоящему_источнику_оговорки_не_несёт | F73: Иначе оговорка обесценится: она стоит на каждом ответе и её перестают читать. | G73: 1
A74: 73 | B74: контрактные | C74: contract/test_llm_gateway.py | E74: test_хватает_одного_синтетического_фрагмента | F74: Смесь настоящего и выдуманного — самый опасный случай: ответ выглядит обоснованным, а часть его построена на составленной нами процедуре. | G74: 1
A75: 74 | B75: контрактные | C75: contract/test_llm_gateway.py | E75: test_расход_из_последнего_куска_доходит_до_события_завершения | F75: Кусок с расходом не несёт текста, и его легко потерять. | G75: 1
A76: 75 | B76: контрактные | C76: contract/test_llm_gateway.py | E76: test_потоковый_путь_запрашивает_расход_у_провайдера | F76: Без stream_options провайдер расход не присылает вовсе — проверено на обоих. Параметр обязан уходить именно в потоковом вызове. | G76: 1
A77: 76 | B77: контрактные | C77: contract/test_llm_gateway.py | E77: test_молчание_провайдера_о_расходе_не_ломает_поток | F77: Провайдер может не прислать расход — тогда ноль, но ответ доходит. | G77: 1
A78: 77 | B78: контрактные | C78: contract/test_llm_gateway.py | E78: test_поток_пишет_событие_использования | F78: Поток пишет событие использования | G78: 1
A79: 78 | B79: контрактные | C79: contract/test_llm_gateway.py | E79: test_ответ_целиком_пишет_событие_использования | F79: Ответ целиком пишет событие использования | G79: 1
... A86: 85 | B86: контрактные | C86: contract/test_llm_gateway.py | E86: test_ответ_вне_выборки_судье_не_отдаётся | F86: Ответ вне выборки судье не отдаётся | G86: 1
A87: 86 | B87: контрактные | C87: contract/test_local_model_live.py | E87: test_модель_поднята_и_загружена | F87: Преполёт на живой Ollama: сервис отвечает, нужная модель на месте. | G87: 1 | H87: живой тест (нужна Ollama, в обычном прогоне выключен)
A88: 87 | B88: контрактные | C88: contract/test_local_model_live.py | E88: test_модель_отвечает_по_русски | F88: Модель отвечает по русски | G88: 1 | H88: живой тест (нужна Ollama, в обычном прогоне выключен)
A89: 88 | B89: контрактные | C89: contract/test_local_model_live.py | E89: test_ответ_приходит_потоком_а_не_одним_куском | F89: Правило потоковой выдачи: локальный backend обязан уметь поток так же, как внешний. | G89: 1 | H89: живой тест (нужна Ollama, в обычном прогоне выключен)
A90: 89 | B90: контрактные | C90: contract/test_orchestrator.py | E90: test_прямой_ответ_не_вызывает_провайдера | F90: Требование ADR-100: ответ не стоит ни токенов, ни ожидания. | G90: 1
A91: 90 | B91: контрактные | C91: contract/test_orchestrator.py | E91: test_оговорка_доходит_обоими_путями | F91: Отметка актуальности бесполезна, если теряется в одном из режимов. | G91: 1
A92: 91 | B92: контрактные | C92: contract/test_orchestrator.py | E92: test_путь_ответа_виден_в_маршрутизации | F92: Иначе прямой ответ неотличим от сгенерированного при разборе жалобы. | G92: 1
A93: 92 | B93: контрактные | C93: contract/test_orchestrator.py | E93: test_молчание_ответчика_уводит_на_обычный_путь | F93: «Не мой случай» не должно превращаться в отказ. | G93: 1
A94: 93 | B94: контрактные | C94: contract/test_orchestrator.py | E94: test_ответчики_опрашиваются_по_порядку | F94: Первый, кто взялся, и отвечает: иначе порядок стал бы случайным, а с ним и ответ на вопрос, попадающий сразу в две темы. | G94: 1
A95: 94 | B95: контрактные | C95: contract/test_orchestrator.py | E95: test_лимиты_проверяются_и_на_прямом_пути | F95: Запрос, отвечаемый без модели, до шлюза не доходит. | G95: 1
A96: 95 | B96: контрактные | C96: contract/test_orchestrator.py | E96: test_отказ_хранилища_на_прямом_пути_даёт_503 | F96: ADR-400: недоступность хранилища — это 503, а не 429. | G96: 1
A97: 96 | B97: контрактные | C97: contract/test_orchestrator.py | E97: test_контекст_ищется_и_доходит_до_шлюза | F97: Backend ищет, шлюз получает промпт с уже собранным контекстом. | G97: 1
A98: 97 | B98: контрактные | C98: contract/test_orchestrator.py | E98: test_переданный_контекст_не_перетирается | F98: Служебные вызовы передают контекст сами. | G98: 1
...

Sheet Файлы
A1: Уровень | B1: Файл | C1: О чём модуль | D1: Тестов (функций) | E1: Кейсов
A2: контрактные | B2: contract/test_api.py | C2: Проверки HTTP-интерфейса. | D2: =COUNTIF('Тесты'!$C$2:$C$718,B2) | E2: =SUMIF('Тесты'!$C$2:$C$718,B2,'Тесты'!$G$2:$G$718)
A3: контрактные | B3: contract/test_api_spec.py | C3: Проверки спецификации API. | D3: =COUNTIF('Тесты'!$C$2:$C$718,B3) | E3: =SUMIF('Тесты'!$C$2:$C$718,B3,'Тесты'!$G$2:$G$718)
A4: контрактные | B4: contract/test_llm_gateway.py | C4: Проверки шлюза к модели. | D4: =COUNTIF('Тесты'!$C$2:$C$718,B4) | E4: =SUMIF('Тесты'!$C$2:$C$718,B4,'Тесты'!$G$2:$G$718)
A5: контрактные | B5: contract/test_local_model_live.py | C5: Живая проверка на реальной модели. | D5: =COUNTIF('Тесты'!$C$2:$C$718,B5) | E5: =SUMIF('Тесты'!$C$2:$C$718,B5,'Тесты'!$G$2:$G$718)
A6: контрактные | B6: contract/test_orchestrator.py | C6: Проверки Backend: выбор пути ответа, поиск контекста, лимиты. | D6: =COUNTIF('Тесты'!$C$2:$C$718,B6) | E6: =SUMIF('Тесты'!$C$2:$C$718,B6,'Тесты'!$G$2:$G$718)
A7: контрактные | B7: contract/test_orchestrator_multi.py | C7: Backend: несколько задач в одной реплике — ответ на каждую часть. | D7: =COUNTIF('Тесты'!$C$2:$C$718,B7) | E7: =SUMIF('Тесты'!$C$2:$C$718,B7,'Тесты'!$G$2:$G$718)
A8: контрактные | B8: contract/test_provider_contract.py | C8: Контрактный тест провайдерского уровня. | D8: =COUNTIF('Тесты'!$C$2:$C$718,B8) | E8: =SUMIF('Тесты'!$C$2:$C$718,B8,'Тесты'!$G$2:$G$718)
A9: модульные | B9: unit/test_adapters.py | C9: Проверки адаптеров записи. | D9: =COUNTIF('Тесты'!$C$2:$C$718,B9) | E9: =SUMIF('Тесты'!$C$2:$C$718,B9,'Тесты'!$G$2:$G$718)
A10: модульные | B10: unit/test_agents.py | C10: Проверки агентов Этапа 1: классификатор и консультант. | D10: =COUNTIF('Тесты'!$C$2:$C$718,B10) | E10: =SUMIF('Тесты'!$C$2:$C$718,B10,'Тесты'!$G$2:$G$718)
A11: модульные | B11: unit/test_answer_judge.py | C11: Проверки судьи качества ответа (LLM-judge). | D11: =COUNTIF('Тесты'!$C$2:$C$718,B11) | E11: =SUMIF('Тесты'!$C$2:$C$718,B11,'Тесты'!$G$2:$G$718)
A12: модульные | B12: unit/test_billing_answer.py | C12: Проверки ответа о фактах лицевого счёта. | D12: =COUNTIF('Тесты'!$C$2:$C$718,B12) | E12: =SUMIF('Тесты'!$C$2:$C$718,B12,'Тесты'!$G$2:$G$718)
A13: модульные | B13: unit/test_billing_source.py | C13: Проверки доступа к данным Биллинга и личного кабинета. | D13: =COUNTIF('Тесты'!$C$2:$C$718,B13) | E13: =SUMIF('Тесты'!$C$2:$C$718,B13,'Тесты'!$G$2:$G$718)
... A53: модульные | B53: unit/test_usage_store.py | C53: Проверки хранилища событий использования (Postgres). | D53: =COUNTIF('Тесты'!$C$2:$C$718,B53) | E53: =SUMIF('Тесты'!$C$2:$C$718,B53,'Тесты'!$G$2:$G$718)
